Workbook

Sheet Sheet2
A3: Row Labels
A4: Alabama
A5: Phone
A6: Physical
A7: Social Media
A8: Alaska
A9: Mobile App
A10: Phone
A11: Physical
A12: Social Media
A13: Website
A14: Arizona
... A272: Grand Total

Sheet Electronic Shop Sales Dataset
A1: productID | B1: Unique_Product_ID | C1: product_name | D1: product_price | E1: number_of_ordered_items | F1: order_status | G1: customer_name | H1: location | I1: latitude | J1: longitude | K1: channel_of_ordering | L1: date | M1: Clean_Date | N1: Revenue | O1: Discounts | P1: Customer_Type | Q1: Month_name | R1: Product Age
A2: P00011 | B2: ='Electronic Shop Sales Dataset'!$A2&"-"&'Electronic Shop Sales Dataset'!$C2 -> P00011-Smartwatch | C2: Smartwatch | D2: 244.74 | E2: 2 | F2: In Process | G2: Heather Swanson | H2: Arizona | I2: 33.729759 | J2: -111.43122 | K2: Phone | L2: 45292 | M2: =DATEVALUE(TEXT(L2,"mm/dd/yy")) -> 45292 | N2: ='Electronic Shop Sales Dataset'!$D2*'Electronic Shop Sales Dataset'!$E2 -> 489.48 | O2: {=_xlfn.IFS($K2="Website",$N2*0.05, $K2="Mobile App",$N2*0.05,TRUE,0)} -> 0 | P2: =IF(COUNTIF($G$2:G577,G2)>1,"Returning","New") -> New | Q2: =TEXT(M2,"mmmm") -> January | R2: {=IF(C2:C577="Laptop","Old Stock","New Arrival")} -> New Arrival | S2: Unique Products | T2: Count_of_UP | U2: Unique Channels | V2: Count_of_Chan | W2: Unique Location | X2: Count_ofLOc | Z2: =COUNTIFS(H2:H577,W3,K2:K577,U3) -> 5
A3: P00011 | B3: ='Electronic Shop Sales Dataset'!$A3&"-"&'Electronic Shop Sales Dataset'!$C3 -> P00011-Scanner | C3: Scanner | D3: 270.96 | E3: 5 | F3: Delivered | G3: Kerry Hanson | H3: Illinois | I3: 40.349457 | J3: -88.986137 | K3: Website | L3: 45293 | M3: =DATEVALUE(TEXT(L3,"mm/dd/yy")) -> 45293 | N3: ='Electronic Shop Sales Dataset'!$D3*'Electronic Shop Sales Dataset'!$E3 -> 1354.8 | O3: {=_xlfn.IFS($K3="Website",$N3*0.05, $K3="Mobile App",$N3*0.05,TRUE,0)} -> 67.74 | P3: =IF(COUNTIF($G$2:G578,G3)>1,"Returning","New") -> New | Q3: =TEXT(M3,"mmmm") -> January | R3: New Arrival | S3: {=_xlfn.UNIQUE(C2:C577)} -> Smartwatch | T3: =COUNTA(_xlfn.ANCHORARRAY(S3)) -> 24 | U3: {=_xlfn.UNIQUE(K2:K577)} -> Phone | V3: =COUNTA(_xlfn.ANCHORARRAY(U3)) -> 5 | W3: {=_xlfn.UNIQUE(H2:H577)} -> Arizona | X3: =COUNTA(_xlfn.ANCHORARRAY(W3)) -> 50
A4: P00011 | B4: ='Electronic Shop Sales Dataset'!$A4&"-"&'Electronic Shop Sales Dataset'!$C4 -> P00011-USB Drive | C4: USB Drive | D4: 5.44 | E4: 2 | F4: Canceled | G4: Antonio Warner | H4: Pennsylvania | I4: 40.590752 | J4: -77.209755 | K4: Social Media | L4: 45293 | M4: =DATEVALUE(TEXT(L4,"mm/dd/yy")) -> 45293 | N4: ='Electronic Shop Sales Dataset'!$D4*'Electronic Shop Sales Dataset'!$E4 -> 10.88 | O4: {=_xlfn.IFS($K4="Website",$N4*0.05, $K4="Mobile App",$N4*0.05,TRUE,0)} -> 0 | P4: =IF(COUNTIF($G$2:G579,G4)>1,"Returning","New") -> New | Q4: =TEXT(M4,"mmmm") -> January | R4: New Arrival | S4: Scanner | U4: Website | W4: Illinois
A5: P00004 | B5: ='Electronic Shop Sales Dataset'!$A5&"-"&'Electronic Shop Sales Dataset'!$C5 -> P00004-Printer | C5: Printer | D5: 279.8 | E5: 1 | F5: Canceled | G5: Rachel Murphy | H5: Connecticut | I5: 41.597782 | J5: -72.755371 | K5: Website | L5: 45293 | M5: =DATEVALUE(TEXT(L5,"mm/dd/yy")) -> 45293 | N5: ='Electronic Shop Sales Dataset'!$D5*'Electronic Shop Sales Dataset'!$E5 -> 279.8 | O5: {=_xlfn.IFS($K5="Website",$N5*0.05, $K5="Mobile App",$N5*0.05,TRUE,0)} -> 13.99 | P5: =IF(COUNTIF($G$2:G580,G5)>1,"Returning","New") -> New | Q5: =TEXT(M5,"mmmm") -> January | R5: New Arrival | S5: USB Drive | U5: Social Media | W5: Pennsylvania
A6: P00007 | B6: ='Electronic Shop Sales Dataset'!$A6&"-"&'Electronic Shop Sales Dataset'!$C6 -> P00007-Tablet | C6: Tablet | D6: 796.53 | E6: 2 | F6: In Process | G6: Erik Sandoval | H6: Mississippi | I6: 32.741646 | J6: -89.678696 | K6: Phone | L6: 45293 | M6: =DATEVALUE(TEXT(L6,"mm/dd/yy")) -> 45293 | N6: ='Electronic Shop Sales Dataset'!$D6*'Electronic Shop Sales Dataset'!$E6 -> 1593.06 | O6: {=_xlfn.IFS($K6="Website",$N6*0.05, $K6="Mobile App",$N6*0.05,TRUE,0)} -> 0 | P6: =IF(COUNTIF($G$2:G581,G6)>1,"Returning","New") -> New | Q6: =TEXT(M6,"mmmm") -> January | R6: New Arrival | S6: Printer | U6: Mobile App | W6: Connecticut
A7: P00006 | B7: ='Electronic Shop Sales Dataset'!$A7&"-"&'Electronic Shop Sales Dataset'!$C7 -> P00006-Power Bank | C7: Power Bank | D7: 49.38 | E7: 1 | F7: In Process | G7: Kristy Morgan | H7: Delaware | I7: 39.318523 | J7: -75.507141 | K7: Website | L7: 45294 | M7: =DATEVALUE(TEXT(L7,"mm/dd/yy")) -> 45294 | N7: ='Electronic Shop Sales Dataset'!$D7*'Electronic Shop Sales Dataset'!$E7 -> 49.38 | O7: {=_xlfn.IFS($K7="Website",$N7*0.05, $K7="Mobile App",$N7*0.05,TRUE,0)} -> 2.469 | P7: =IF(COUNTIF($G$2:G582,G7)>1,"Returning","New") -> New | Q7: =TEXT(M7,"mmmm") -> January | R7: New Arrival | S7: Tablet | U7: Physical | W7: Mississippi
A8: P00004 | B8: ='Electronic Shop Sales Dataset'!$A8&"-"&'Electronic Shop Sales Dataset'!$C8 -> P00004-Charger | C8: Charger | D8: 18.02 | E8: 2 | F8: Canceled | G8: Allison Richardson | H8: Oklahoma | I8: 35.565342 | J8: -96.928917 | K8: Social Media | L8: 45294 | M8: =DATEVALUE(TEXT(L8,"mm/dd/yy")) -> 45294 | N8: ='Electronic Shop Sales Dataset'!$D8*'Electronic Shop Sales Dataset'!$E8 -> 36.04 | O8: {=_xlfn.IFS($K8="Website",$N8*0.05, $K8="Mobile App",$N8*0.05,TRUE,0)} -> 0 | P8: =IF(COUNTIF($G$2:G583,G8)>1,"Returning","New") -> New | Q8: =TEXT(M8,"mmmm") -> January | R8: New Arrival | S8: Power Bank | W8: Delaware
A9: P00013 | B9: ='Electronic Shop Sales Dataset'!$A9&"-"&'Electronic Shop Sales Dataset'!$C9 -> P00013-Tablet | C9: Tablet | D9: 398.73 | E9: 4 | F9: Canceled | G9: Melissa Mendez | H9: Illinois | I9: 40.349457 | J9: -88.986137 | K9: Mobile App | L9: 45294 | M9: =DATEVALUE(TEXT(L9,"mm/dd/yy")) -> 45294 | N9: ='Electronic Shop Sales Dataset'!$D9*'Electronic Shop Sales Dataset'!$E9 -> 1594.92 | O9: {=_xlfn.IFS($K9="Website",$N9*0.05, $K9="Mobile App",$N9*0.05,TRUE,0)} -> 79.746 | P9: =IF(COUNTIF($G$2:G584,G9)>1,"Returning","New") -> New | Q9: =TEXT(M9,"mmmm") -> January | R9: New Arrival | S9: Charger | W9: Oklahoma
A10: P00015 | B10: ='Electronic Shop Sales Dataset'!$A10&"-"&'Electronic Shop Sales Dataset'!$C10 -> P00015-Power Bank | C10: Power Bank | D10: 87.43 | E10: 4 | F10: On Hold | G10: Anthony Reeves | H10: Massachusetts | I10: 42.230171 | J10: -71.530106 | K10: Physical | L10: 45295 | M10: =DATEVALUE(TEXT(L10,"mm/dd/yy")) -> 45295 | N10: ='Electronic Shop Sales Dataset'!$D10*'Electronic Shop Sales Dataset'!$E10 -> 349.72 | O10: {=_xlfn.IFS($K10="Website",$N10*0.05, $K10="Mobile App",$N10*0.05,TRUE,0)} -> 0 | P10: =IF(COUNTIF($G$2:G585,G10)>1,"Returning","New") -> New | Q10: =TEXT(M10,"mmmm") -> January | R10: New Arrival | S10: Mouse | W10: Massachusetts
A11: P00017 | B11: ='Electronic Shop Sales Dataset'!$A11&"-"&'Electronic Shop Sales Dataset'!$C11 -> P00017-Mouse | C11: Mouse | D11: 19.42 | E11: 1 | F11: On Hold | G11: Angelica Knight | H11: Florida | I11: 27.766279 | J11: -81.686783 | K11: Mobile App | L11: 45295 | M11: =DATEVALUE(TEXT(L11,"mm/dd/yy")) -> 45295 | N11: ='Electronic Shop Sales Dataset'!$D11*'Electronic Shop Sales Dataset'!$E11 -> 19.42 | O11: {=_xlfn.IFS($K11="Website",$N11*0.05, $K11="Mobile App",$N11*0.05,TRUE,0)} -> 0.971 | P11: =IF(COUNTIF($G$2:G586,G11)>1,"Returning","New") -> New | Q11: =TEXT(M11,"mmmm") -> January | R11: New Arrival | S11: VR Headset | W11: Florida
A12: P00018 | B12: ='Electronic Shop Sales Dataset'!$A12&"-"&'Electronic Shop Sales Dataset'!$C12 -> P00018-Power Bank | C12: Power Bank | D12: 91.69 | E12: 2 | F12: On Hold | G12: Michael Miller | H12: Michigan | I12: 43.326618 | J12: -84.536095 | K12: Website | L12: 45295 | M12: =DATEVALUE(TEXT(L12,"mm/dd/yy")) -> 45295 | N12: ='Electronic Shop Sales Dataset'!$D12*'Electronic Shop Sales Dataset'!$E12 -> 183.38 | O12: {=_xlfn.IFS($K12="Website",$N12*0.05, $K12="Mobile App",$N12*0.05,TRUE,0)} -> 9.169 | P12: =IF(COUNTIF($G$2:G587,G12)>1,"Returning","New") -> New | Q12: =TEXT(M12,"mmmm") -> January | R12: New Arrival | S12: Laptop | W12: Michigan
A13: P00008 | B13: ='Electronic Shop Sales Dataset'!$A13&"-"&'Electronic Shop Sales Dataset'!$C13 -> P00008-Power Bank | C13: Power Bank | D13: 49.23 | E13: 1 | F13: Canceled | G13: Kayla Jackson | H13: West Virginia | I13: 38.491226 | J13: -80.954456 | K13: Website | L13: 45295 | M13: =DATEVALUE(TEXT(L13,"mm/dd/yy")) -> 45295 | N13: ='Electronic Shop Sales Dataset'!$D13*'Electronic Shop Sales Dataset'!$E13 -> 49.23 | O13: {=_xlfn.IFS($K13="Website",$N13*0.05, $K13="Mobile App",$N13*0.05,TRUE,0)} -> 2.4615 | P13: =IF(COUNTIF($G$2:G588,G13)>1,"Returning","New") -> New | Q13: =TEXT(M13,"mmmm") -> January | R13: New Arrival | S13: Drone | W13: West Virginia
A14: P00013 | B14: ='Electronic Shop Sales Dataset'!$A14&"-"&'Electronic Shop Sales Dataset'!$C14 -> P00013-Smartwatch | C14: Smartwatch | D14: 256.77 | E14: 5 | F14: Canceled | G14: Marco Jennings | H14: Colorado | I14: 39.059811 | J14: -105.3111 | K14: Phone | L14: 45295 | M14: =DATEVALUE(TEXT(L14,"mm/dd/yy")) -> 45295 | N14: ='Electronic Shop Sales Dataset'!$D14*'Electronic Shop Sales Dataset'!$E14 -> 1283.85 | O14: {=_xlfn.IFS($K14="Website",$N14*0.05, $K14="Mobile App",$N14*0.05,TRUE,0)} -> 0 | P14: =IF(COUNTIF($G$2:G589,G14)>1,"Returning","New") -> New | Q14: =TEXT(M14,"mmmm") -> January | R14: New Arrival | S14: Headphones | W14: Colorado
A15: P00004 | B15: ='Electronic Shop Sales Dataset'!$A15&"-"&'Electronic Shop Sales Dataset'!$C15 -> P00004-VR Headset | C15: VR Headset | D15: 811.34 | E15: 1 | F15: Canceled | G15: Ryan Lopez | H15: Arkansas | I15: 34.969704 | J15: -92.373123 | K15: Mobile App | L15: 45296 | M15: =DATEVALUE(TEXT(L15,"mm/dd/yy")) -> 45296 | N15: ='Electronic Shop Sales Dataset'!$D15*'Electronic Shop Sales Dataset'!$E15 -> 811.34 | O15: {=_xlfn.IFS($K15="Website",$N15*0.05, $K15="Mobile App",$N15*0.05,TRUE,0)} -> 40.567 | P15: =IF(COUNTIF($G$2:G590,G15)>1,"Returning","New") -> New | Q15: =TEXT(M15,"mmmm") -> January | R15: New Arrival | S15: Projector | W15: Arkansas
A16: P00012 | B16: ='Electronic Shop Sales Dataset'!$A16&"-"&'Electronic Shop Sales Dataset'!$C16 -> P00012-Laptop | C16: Laptop | D16: 1938.62 | E16: 3 | F16: Delivered | G16: Danielle Hall | H16: Florida | I16: 27.766279 | J16: -81.686783 | K16: Social Media | L16: 45296 | M16: =DATEVALUE(TEXT(L16,"mm/dd/yy")) -> 45296 | N16: ='Electronic Shop Sales Dataset'!$D16*'Electronic Shop Sales Dataset'!$E16 -> 5815.86 | O16: {=_xlfn.IFS($K16="Website",$N16*0.05, $K16="Mobile App",$N16*0.05,TRUE,0)} -> 0 | P16: =IF(COUNTIF($G$2:G591,G16)>1,"Returning","New") -> New | Q16: =TEXT(M16,"mmmm") -> January | R16: Old Stock | S16: Graphics Card | W16: Utah
A17: P00013 | B17: ='Electronic Shop Sales Dataset'!$A17&"-"&'Electronic Shop Sales Dataset'!$C17 -> P00013-Drone | C17: Drone | D17: 1708.47 | E17: 1 | F17: Delivered | G17: Maria Wolfe | H17: Utah | I17: 40.150032 | J17: -111.86243 | K17: Phone | L17: 45296 | M17: =DATEVALUE(TEXT(L17,"mm/dd/yy")) -> 45296 | N17: ='Electronic Shop Sales Dataset'!$D17*'Electronic Shop Sales Dataset'!$E17 -> 1708.47 | O17: {=_xlfn.IFS($K17="Website",$N17*0.05, $K17="Mobile App",$N17*0.05,TRUE,0)} -> 0 | P17: =IF(COUNTIF($G$2:G592,G17)>1,"Returning","New") -> New | Q17: =TEXT(M17,"mmmm") -> January | R17: New Arrival | S17: Monitor | W17: New Jersey
A18: P00018 | B18: ='Electronic Shop Sales Dataset'!$A18&"-"&'Electronic Shop Sales Dataset'!$C18 -> P00018-Printer | C18: Printer | D18: 346.36 | E18: 2 | F18: In Process | G18: Sarah Mcdaniel | H18: New Jersey | I18: 40.298904 | J18: -74.521011 | K18: Physical | L18: 45299 | M18: =DATEVALUE(TEXT(L18,"mm/dd/yy")) -> 45299 | N18: ='Electronic Shop Sales Dataset'!$D18*'Electronic Shop Sales Dataset'!$E18 -> 692.72 | O18: {=_xlfn.IFS($K18="Website",$N18*0.05, $K18="Mobile App",$N18*0.05,TRUE,0)} -> 0 | P18: =IF(COUNTIF($G$2:G593,G18)>1,"Returning","New") -> New | Q18: =TEXT(M18,"mmmm") -> January | R18: New Arrival | S18: Hard Disk | W18: North Carolina
A19: P00002 | B19: ='Electronic Shop Sales Dataset'!$A19&"-"&'Electronic Shop Sales Dataset'!$C19 -> P00002-Tablet | C19: Tablet | D19: 777.81 | E19: 4 | F19: Canceled | G19: Eric Arnold | H19: North Carolina | I19: 35.630066 | J19: -79.806419 | K19: Physical | L19: 45301 | M19: =DATEVALUE(TEXT(L19,"mm/dd/yy")) -> 45301 | N19: ='Electronic Shop Sales Dataset'!$D19*'Electronic Shop Sales Dataset'!$E19 -> 3111.24 | O19: {=_xlfn.IFS($K19="Website",$N19*0.05, $K19="Mobile App",$N19*0.05,TRUE,0)} -> 0 | P19: =IF(COUNTIF($G$2:G594,G19)>1,"Returning","New") -> New | Q19: =TEXT(M19,"mmmm") -> January | R19: New Arrival | S19: Camera | W19: Tennessee
... A26: P00022 | B26: ='Electronic Shop Sales Dataset'!$A26&"-"&'Electronic Shop Sales Dataset'!$C26 -> P00022-Laptop | C26: Laptop | D26: 1843.37 | E26: 2 | F26: Canceled | G26: Stephanie Payne | H26: Rhode Island | I26: 41.680893 | J26: -71.51178 | K26: Phone | L26: 45302 | M26: =DATEVALUE(TEXT(L26,"mm/dd/yy")) -> 45302 | N26: ='Electronic Shop Sales Dataset'!$D26*'Electronic Shop Sales Dataset'!$E26 -> 3686.74 | O26: {=_xlfn.IFS($K26="Website",$N26*0.05, $K26="Mobile App",$N26*0.05,TRUE,0)} -> 0 | P26: =IF(COUNTIF($G$2:G601,G26)>1,"Returning","New") -> New | Q26: =TEXT(M26,"mmmm") -> January | R26: Old Stock | S26: Smartphone | W26: Louisiana
A27: P00008 | B27: ='Electronic Shop Sales Dataset'!$A27&"-"&'Electronic Shop Sales Dataset'!$C27 -> P00008-Hard Disk | C27: Hard Disk | D27: 68.62 | E27: 3 | F27: On Hold | G27: Anthony Sanchez | H27: Michigan | I27: 43.326618 | J27: -84.536095 | K27: Social Media | L27: 45302 | M27: =DATEVALUE(TEXT(L27,"mm/dd/yy")) -> 45302 | N27: ='Electronic Shop Sales Dataset'!$D27*'Electronic Shop Sales Dataset'!$E27 -> 205.86 | O27: {=_xlfn.IFS($K27="Website",$N27*0.05, $K27="Mobile App",$N27*0.05,TRUE,0)} -> 0 | P27: =IF(COUNTIF($G$2:G602,G27)>1,"Returning","New") -> New | Q27: =TEXT(M27,"mmmm") -> January | R27: New Arrival | W27: Hawaii
A28: P00011 | B28: ='Electronic Shop Sales Dataset'!$A28&"-"&'Electronic Shop Sales Dataset'!$C28 -> P00011-Camera | C28: Camera | D28: 1553.53 | E28: 5 | F28: Canceled | G28: Lance Crosby | H28: New Hampshire | I28: 43.452492 | J28: -71.563896 | K28: Website | L28: 45302 | M28: =DATEVALUE(TEXT(L28,"mm/dd/yy")) -> 45302 | N28: ='Electronic Shop Sales Dataset'!$D28*'Electronic Shop Sales Dataset'!$E28 -> 7767.65 | O28: {=_xlfn.IFS($K28="Website",$N28*0.05, $K28="Mobile App",$N28*0.05,TRUE,0)} -> 388.3825 | P28: =IF(COUNTIF($G$2:G603,G28)>1,"Returning","New") -> New | Q28: =TEXT(M28,"mmmm") -> January | R28: New Arrival | W28: New Mexico
A29: P00023 | B29: ='Electronic Shop Sales Dataset'!$A29&"-"&'Electronic Shop Sales Dataset'!$C29 -> P00023-Charger | C29: Charger | D29: 15.66 | E29: 5 | F29: Canceled | G29: Ricardo Morrow | H29: Louisiana | I29: 31.169546 | J29: -91.867805 | K29: Social Media | L29: 45303 | M29: =DATEVALUE(TEXT(L29,"mm/dd/yy")) -> 45303 | N29: ='Electronic Shop Sales Dataset'!$D29*'Electronic Shop Sales Dataset'!$E29 -> 78.3 | O29: {=_xlfn.IFS($K29="Website",$N29*0.05, $K29="Mobile App",$N29*0.05,TRUE,0)} -> 0 | P29: =IF(COUNTIF($G$2:G604,G29)>1,"Returning","New") -> New | Q29: =TEXT(M29,"mmmm") -> January | R29: New Arrival | W29: Ohio
A30: P00001 | B30: ='Electronic Shop Sales Dataset'!$A30&"-"&'Electronic Shop Sales Dataset'!$C30 -> P00001-Gaming Console | C30: Gaming Console | D30: 392.04 | E30: 2 | F30: Canceled | G30: Samantha Delgado | H30: Hawaii | I30: 21.094318 | J30: -157.49834 | K30: Social Media | L30: 45303 | M30: =DATEVALUE(TEXT(L30,"mm/dd/yy")) -> 45303 | N30: ='Electronic Shop Sales Dataset'!$D30*'Electronic Shop Sales Dataset'!$E30 -> 784.08 | O30: {=_xlfn.IFS($K30="Website",$N30*0.05, $K30="Mobile App",$N30*0.05,TRUE,0)} -> 0 | P30: =IF(COUNTIF($G$2:G605,G30)>1,"Returning","New") -> New | Q30: =TEXT(M30,"mmmm") -> January | R30: New Arrival | W30: Alabama
A31: P00004 | B31: ='Electronic Shop Sales Dataset'!$A31&"-"&'Electronic Shop Sales Dataset'!$C31 -> P00004-Laptop | C31: Laptop | D31: 646.55 | E31: 3 | F31: Delivered | G31: Dr. Heather Burnett | H31: Tennessee | I31: 35.747845 | J31: -86.692345 | K31: Social Media | L31: 45303 | M31: =DATEVALUE(TEXT(L31,"mm/dd/yy")) -> 45303 | N31: ='Electronic Shop Sales Dataset'!$D31*'Electronic Shop Sales Dataset'!$E31 -> 1939.65 | O31: {=_xlfn.IFS($K31="Website",$N31*0.05, $K31="Mobile App",$N31*0.05,TRUE,0)} -> 0 | P31: =IF(COUNTIF($G$2:G606,G31)>1,"Returning","New") -> New | Q31: =TEXT(M31,"mmmm") -> January | R31: Old Stock | W31: Kansas
A32: P00012 | B32: ='Electronic Shop Sales Dataset'!$A32&"-"&'Electronic Shop Sales Dataset'!$C32 -> P00012-Mouse | C32: Mouse | D32: 44.42 | E32: 3 | F32: Delivered | G32: Nathan Morales | H32: New Mexico | I32: 34.840515 | J32: -106.24848 | K32: Phone | L32: 45304 | M32: =DATEVALUE(TEXT(L32,"mm/dd/yy")) -> 45304 | N32: ='Electronic Shop Sales Dataset'!$D32*'Electronic Shop Sales Dataset'!$E32 -> 133.26 | O32: {=_xlfn.IFS($K32="Website",$N32*0.05, $K32="Mobile App",$N32*0.05,TRUE,0)} -> 0 | P32: =IF(COUNTIF($G$2:G607,G32)>1,"Returning","New") -> New | Q32: =TEXT(M32,"mmmm") -> January | R32: New Arrival | W32: Oregon
A33: P00018 | B33: ='Electronic Shop Sales Dataset'!$A33&"-"&'Electronic Shop Sales Dataset'!$C33 -> P00018-Hard Disk | C33: Hard Disk | D33: 107.94 | E33: 5 | F33: On Hold | G33: Joshua Howard | H33: Texas | I33: 31.054487 | J33: -97.563461 | K33: Phone | L33: 45304 | M33: =DATEVALUE(TEXT(L33,"mm/dd/yy")) -> 45304 | N33: ='Electronic Shop Sales Dataset'!$D33*'Electronic Shop Sales Dataset'!$E33 -> 539.7 | O33: {=_xlfn.IFS($K33="Website",$N33*0.05, $K33="Mobile App",$N33*0.05,TRUE,0)} -> 0 | P33: =IF(COUNTIF($G$2:G608,G33)>1,"Returning","New") -> New | Q33: =TEXT(M33,"mmmm") -> January | R33: New Arrival | W33: South Carolina
A34: P00021 | B34: ='Electronic Shop Sales Dataset'!$A34&"-"&'Electronic Shop Sales Dataset'!$C34 -> P00021-Tablet | C34: Tablet | D34: 401.34 | E34: 3 | F34: In Process | G34: Amanda Cain | H34: Pennsylvania | I34: 40.590752 | J34: -77.209755 | K34: Physical | L34: 45305 | M34: =DATEVALUE(TEXT(L34,"mm/dd/yy")) -> 45305 | N34: ='Electronic Shop Sales Dataset'!$D34*'Electronic Shop Sales Dataset'!$E34 -> 1204.02 | O34: {=_xlfn.IFS($K34="Website",$N34*0.05, $K34="Mobile App",$N34*0.05,TRUE,0)} -> 0 | P34: =IF(COUNTIF($G$2:G609,G34)>1,"Returning","New") -> New | Q34: =TEXT(M34,"mmmm") -> January | R34: New Arrival | W34: Idaho
A35: P00002 | B35: ='Electronic Shop Sales Dataset'!$A35&"-"&'Electronic Shop Sales Dataset'!$C35 -> P00002-Scanner | C35: Scanner | D35: 135.26 | E35: 1 | F35: Delivered | G35: Eddie Ortiz | H35: Ohio | I35: 40.388783 | J35: -82.764915 | K35: Social Media | L35: 45306 | M35: =DATEVALUE(TEXT(L35,"mm/dd/yy")) -> 45306 | N35: ='Electronic Shop Sales Dataset'!$D35*'Electronic Shop Sales Dataset'!$E35 -> 135.26 | O35: {=_xlfn.IFS($K35="Website",$N35*0.05, $K35="Mobile App",$N35*0.05,TRUE,0)} -> 0 | P35: =IF(COUNTIF($G$2:G610,G35)>1,"Returning","New") -> New | Q35: =TEXT(M35,"mmmm") -> January | R35: New Arrival | W35: Wisconsin
A36: P00016 | B36: ='Electronic Shop Sales Dataset'!$A36&"-"&'Electronic Shop Sales Dataset'!$C36 -> P00016-Drone | C36: Drone | D36: 1458.91 | E36: 3 | F36: In Process | G36: Kyle Gomez | H36: Connecticut | I36: 41.597782 | J36: -72.755371 | K36: Physical | L36: 45307 | M36: =DATEVALUE(TEXT(L36,"mm/dd/yy")) -> 45307 | N36: ='Electronic Shop Sales Dataset'!$D36*'Electronic Shop Sales Dataset'!$E36 -> 4376.73 | O36: {=_xlfn.IFS($K36="Website",$N36*0.05, $K36="Mobile App",$N36*0.05,TRUE,0)} -> 0 | P36: =IF(COUNTIF($G$2:G611,G36)>1,"Returning","New") -> New | Q36: =TEXT(M36,"mmmm") -> January | R36: New Arrival | W36: Wyoming
A37: P00014 | B37: ='Electronic Shop Sales Dataset'!$A37&"-"&'Electronic Shop Sales Dataset'!$C37 -> P00014-Keyboard | C37: Keyboard | D37: 123.94 | E37: 5 | F37: Canceled | G37: Gabriel Green | H37: Massachusetts | I37: 42.230171 | J37: -71.530106 | K37: Phone | L37: 45307 | M37: =DATEVALUE(TEXT(L37,"mm/dd/yy")) -> 45307 | N37: ='Electronic Shop Sales Dataset'!$D37*'Electronic Shop Sales Dataset'!$E37 -> 619.7 | O37: {=_xlfn.IFS($K37="Website",$N37*0.05, $K37="Mobile App",$N37*0.05,TRUE,0)} -> 0 | P37: =IF(COUNTIF($G$2:G612,G37)>1,"Returning","New") -> New | Q37: =TEXT(M37,"mmmm") -> January | R37: New Arrival | W37: Montana
A38: P00011 | B38: ='Electronic Shop Sales Dataset'!$A38&"-"&'Electronic Shop Sales Dataset'!$C38 -> P00011-Laptop | C38: Laptop | D38: 1034.25 | E38: 5 | F38: On Hold | G38: James Davis | H38: Massachusetts | I38: 42.230171 | J38: -71.530106 | K38: Phone | L38: 45307 | M38: =DATEVALUE(TEXT(L38,"mm/dd/yy")) -> 45307 | N38: ='Electronic Shop Sales Dataset'!$D38*'Electronic Shop Sales Dataset'!$E38 -> 5171.25 | O38: {=_xlfn.IFS($K38="Website",$N38*0.05, $K38="Mobile App",$N38*0.05,TRUE,0)} -> 0 | P38: =IF(COUNTIF($G$2:G613,G38)>1,"Returning","New") -> New | Q38: =TEXT(M38,"mmmm") -> January | R38: Old Stock | W38: Indiana
... A52: P00003 | B52: ='Electronic Shop Sales Dataset'!$A52&"-"&'Electronic Shop Sales Dataset'!$C52 -> P00003-Router | C52: Router | D52: 146.51 | E52: 1 | F52: Canceled | G52: Sarah Collins | H52: Montana | I52: 46.921925 | J52: -110.45435 | K52: Social Media | L52: 45312 | M52: =DATEVALUE(TEXT(L52,"mm/dd/yy")) -> 45312 | N52: ='Electronic Shop Sales Dataset'!$D52*'Electronic Shop Sales Dataset'!$E52 -> 146.51 | O52: {=_xlfn.IFS($K52="Website",$N52*0.05, $K52="Mobile App",$N52*0.05,TRUE,0)} -> 0 | P52: =IF(COUNTIF($G$2:G627,G52)>1,"Returning","New") -> New | Q52: =TEXT(M52,"mmmm") -> January | R52: New Arrival | W52: New York
A53: P00014 | B53: ='Electronic Shop Sales Dataset'!$A53&"-"&'Electronic Shop Sales Dataset'!$C53 -> P00014-USB Drive | C53: USB Drive | D53: 26.81 | E53: 2 | F53: Delivered | G53: Elizabeth Saunders | H53: Indiana | I53: 39.849426 | J53: -86.258278 | K53: Mobile App | L53: 45312 | M53: =DATEVALUE(TEXT(L53,"mm/dd/yy")) -> 45312 | N53: ='Electronic Shop Sales Dataset'!$D53*'Electronic Shop Sales Dataset'!$E53 -> 53.62 | O53: {=_xlfn.IFS($K53="Website",$N53*0.05, $K53="Mobile App",$N53*0.05,TRUE,0)} -> 2.681 | P53: =IF(COUNTIF($G$2:G628,G53)>1,"Returning","New") -> New | Q53: =TEXT(M53,"mmmm") -> January | R53: New Arrival
A54: P00013 | B54: ='Electronic Shop Sales Dataset'!$A54&"-"&'Electronic Shop Sales Dataset'!$C54 -> P00013-Printer | C54: Printer | D54: 458.57 | E54: 5 | F54: Delivered | G54: Lisa Benitez | H54: Missouri | I54: 38.456085 | J54: -92.288368 | K54: Social Media | L54: 45312 | M54: =DATEVALUE(TEXT(L54,"mm/dd/yy")) -> 45312 | N54: ='Electronic Shop Sales Dataset'!$D54*'Electronic Shop Sales Dataset'!$E54 -> 2292.85 | O54: {=_xlfn.IFS($K54="Website",$N54*0.05, $K54="Mobile App",$N54*0.05,TRUE,0)} -> 0 | P54: =IF(COUNTIF($G$2:G629,G54)>1,"Returning","New") -> New | Q54: =TEXT(M54,"mmmm") -> January | R54: New Arrival
A55: P00005 | B55: ='Electronic Shop Sales Dataset'!$A55&"-"&'Electronic Shop Sales Dataset'!$C55 -> P00005-Smart Home Hub | C55: Smart Home Hub | D55: 130.92 | E55: 3 | F55: In Process | G55: Erica Marshall | H55: Massachusetts | I55: 42.230171 | J55: -71.530106 | K55: Physical | L55: 45313 | M55: =DATEVALUE(TEXT(L55,"mm/dd/yy")) -> 45313 | N55: ='Electronic Shop Sales Dataset'!$D55*'Electronic Shop Sales Dataset'!$E55 -> 392.76 | O55: {=_xlfn.IFS($K55="Website",$N55*0.05, $K55="Mobile App",$N55*0.05,TRUE,0)} -> 0 | P55: =IF(COUNTIF($G$2:G630,G55)>1,"Returning","New") -> New | Q55: =TEXT(M55,"mmmm") -> January | R55: New Arrival
A56: P00016 | B56: ='Electronic Shop Sales Dataset'!$A56&"-"&'Electronic Shop Sales Dataset'!$C56 -> P00016-Camera | C56: Camera | D56: 2680.21 | E56: 2 | F56: On Hold | G56: Lisa Bradford | H56: Hawaii | I56: 21.094318 | J56: -157.49834 | K56: Physical | L56: 45314 | M56: =DATEVALUE(TEXT(L56,"mm/dd/yy")) -> 45314 | N56: ='Electronic Shop Sales Dataset'!$D56*'Electronic Shop Sales Dataset'!$E56 -> 5360.42 | O56: {=_xlfn.IFS($K56="Website",$N56*0.05, $K56="Mobile App",$N56*0.05,TRUE,0)} -> 0 | P56: =IF(COUNTIF($G$2:G631,G56)>1,"Returning","New") -> New | Q56: =TEXT(M56,"mmmm") -> January | R56: New Arrival
A57: P00013 | B57: ='Electronic Shop Sales Dataset'!$A57&"-"&'Electronic Shop Sales Dataset'!$C57 -> P00013-Smart Home Hub | C57: Smart Home Hub | D57: 228.1 | E57: 3 | F57: Canceled | G57: Jennifer Craig | H57: Montana | I57: 46.921925 | J57: -110.45435 | K57: Physical | L57: 45315 | M57: =DATEVALUE(TEXT(L57,"mm/dd/yy")) -> 45315 | N57: ='Electronic Shop Sales Dataset'!$D57*'Electronic Shop Sales Dataset'!$E57 -> 684.3 | O57: {=_xlfn.IFS($K57="Website",$N57*0.05, $K57="Mobile App",$N57*0.05,TRUE,0)} -> 0 | P57: =IF(COUNTIF($G$2:G632,G57)>1,"Returning","New") -> New | Q57: =TEXT(M57,"mmmm") -> January | R57: New Arrival
A58: P00007 | B58: ='Electronic Shop Sales Dataset'!$A58&"-"&'Electronic Shop Sales Dataset'!$C58 -> P00007-Camera | C58: Camera | D58: 1365.9 | E58: 2 | F58: On Hold | G58: Ryan Campbell | H58: Hawaii | I58: 21.094318 | J58: -157.49834 | K58: Mobile App | L58: 45315 | M58: =DATEVALUE(TEXT(L58,"mm/dd/yy")) -> 45315 | N58: ='Electronic Shop Sales Dataset'!$D58*'Electronic Shop Sales Dataset'!$E58 -> 2731.8 | O58: {=_xlfn.IFS($K58="Website",$N58*0.05, $K58="Mobile App",$N58*0.05,TRUE,0)} -> 136.59 | P58: =IF(COUNTIF($G$2:G633,G58)>1,"Returning","New") -> New | Q58: =TEXT(M58,"mmmm") -> January | R58: New Arrival
A59: P00015 | B59: ='Electronic Shop Sales Dataset'!$A59&"-"&'Electronic Shop Sales Dataset'!$C59 -> P00015-Smart TV | C59: Smart TV | D59: 684.64 | E59: 3 | F59: Delivered | G59: Benjamin Roberts | H59: Vermont | I59: 44.045876 | J59: -72.710686 | K59: Phone | L59: 45315 | M59: =DATEVALUE(TEXT(L59,"mm/dd/yy")) -> 45315 | N59: ='Electronic Shop Sales Dataset'!$D59*'Electronic Shop Sales Dataset'!$E59 -> 2053.92 | O59: {=_xlfn.IFS($K59="Website",$N59*0.05, $K59="Mobile App",$N59*0.05,TRUE,0)} -> 0 | P59: =IF(COUNTIF($G$2:G634,G59)>1,"Returning","New") -> New | Q59: =TEXT(M59,"mmmm") -> January | R59: New Arrival
...

Sheet Sheet
B1: Count_of_UP | C1: Unique Channels | D1: Count_of_Chan | E1: Unique Location | F1: Count_ofLOc
A2: {=_xlfn.UNIQUE(#REF!)} -> #REF! | B2: =COUNTA(_xlfn.ANCHORARRAY(A2)) -> 1 | C2: {=_xlfn.UNIQUE(#REF!)} -> #REF! | D2: =COUNTA(_xlfn.ANCHORARRAY(C2)) -> 1 | E2: {=_xlfn.UNIQUE(#REF!)} -> #REF! | F2: =COUNTA(_xlfn.ANCHORARRAY(E2)) -> 1
